Workbook

Sheet Instruktioner
B2: SAMÄGANDE FILMPRODUKTION
B3: Tillägg till SFI:s budgetmall — Equity & Poängregister v1.0
B6: OM DETTA VERKTYG
C7: Detta kalkylblad är ett tillägg till SFI:s standardmall för filmbudget. Det lägger ett poäng- och equity-lager ovanpå den befintliga egeninsats-strukturen utan att ändra budgetens format eller SFI-kompatibilitet.
B9: FLIKAR
B10: ① Instruktioner | C10: Den här sidan. Läs igenom en gång.
B11: ② Projektinställningar | C11: Projektnamn, bolag, fasindelning och poängtabell. Fyll i dessa först.
B12: ③ Egeninsats & Poäng | C12: Huvudregistret. En rad per person per fas. Kopplar till SFI-mallens egeninsats-flik.
B13: ④ Equity Dashboard | C13: Automatisk sammanställning. Visar ägarandelar, waterfall och per-person-utdrag.
B14: ⑤ Fasbudget | C14: Helhetsbudget uppdelad per produktionsfas. Knyter an till SFI-posternas struktur.
B15: ⑦ Personutdrag | C15: Utskrivbart utdrag per person. Visar poänghistorik, ägarandel och waterfall-andel i tre scenarier. En sida per person.
B17: INMATNINGSPRINCIP
B18: Blå text | C18: Inmatningsceller — fyll i dessa manuellt.
B19: Svart text | C19: Formelceller — rör dem inte.
B20: Gul bakgrund | C20: Viktig inmatning som måste fyllas i.
B22: ARBETSFLÖDE
B23: Steg 1 | C23: Fyll i Projektinställningar (namn, faser, poängtabell).
B24: Steg 2 | C24: Fyll i Egeninsats & Poäng — en rad per person per fas.
B25: Steg 3 | C25: Kontrollera Equity Dashboard att summorna stämmer.
B26: Steg 4 | C26: Använd Fasbudget för att fördela budget per produktionsfas.
B27: Steg 5 | C27: Kör Waterfall Simulering vid finansiärsmöten eller Lock-tidpunkter.
B29: LOCK-PUNKTER
B30: Lock 1 — Green Light | C30: Fastställ poäng för F1 (Development) och F2 (Pre-production). Markera datum i Projektinställningar.
B31: Lock 2 — Wrap | C31: Fastställ poäng för F3 (Production). Uppdatera om ny finansiär tillkommit.
B32: Lock 3 — Leverans | C32: Fastställ poäng för F4 (Post) och F5 (Promotion). Slutgiltigt register.

Sheet Projektinställningar
B2: PROJEKTINSTÄLLNINGAR
B4: PROJEKTINFORMATION
B5: Projektnamn | D5: Filmtiteln
B6: Produktionsbolag | D6: AB / HB / Kooperativ
B7: Projektledare / Producent | D7: Namn
B8: Startdatum Development | D8: ÅÅÅÅ-MM-DD
B9: Beräknad inspelningsstart | D9: ÅÅÅÅ-MM-DD
B10: Beräknad leverans | D10: ÅÅÅÅ-MM-DD
B11: Total budget (inkl deferred) | D11: SEK
B12: Varav kontant budget | D12: SEK
B13: Varav egeninsats / deferred | D13: SEK
B16: LOCK-PUNKTER
B17: Lock 1 — Green Light
B18: Lock 2 — Wrap
B19: Lock 3 — Leverans
B22: FASINDELNING & POÄNGTABELL
B23: Fas | C23: Benämning | D23: Aktiveras | E23: Grundpoäng/dag | F23: Riskpremie | G23: Poäng×premie | H23: Kommentar
B24: F1 | C24: Development | D24: JA | E24: 15 | F24: 1.5 | G24: =E24*F24
B25: F2 | C25: Pre-production | D25: JA | E25: 12 | F25: 1.25 | G25: =E25*F25
B26: F3 | C26: Pilot / Testinsp. | D26: NEJ | E26: 12 | F26: 1.25 | G26: =E26*F26
B27: F4 | C27: Production Fas 1 | D27: JA | E27: 10 | F27: 1 | G27: =E27*F27
B28: F5 | C28: Production Fas 2 | D28: NEJ | E28: 10 | F28: 1 | G28: =E28*F28
B29: F6 | C29: Post-production | D29: JA | E29: 10 | F29: 1 | G29: =E29*F29
B30: F7 | C30: Promotion / Lansering | D30: JA | E30: 8 | F30: 1 | G30: =E30*F30
B31: F8 | C31: Övrigt | D31: NEJ | E31: 8 | F31: 1 | G31: =E31*F31
B34: FUNKTIONSKLASS-MULTIPLIKATORER
B35: Klass | C35: Beskrivning | D35: Multiplikator | E35: Exempel
B36: A | C36: Nyckelkreativ / Avdelningsansvarig, unik | D36: 1.5 | E36: Regissör, DOP, Scenograf, Klippare, Producent (lead), Skådespelare i huvudroll
B37: B | C37: Ledande funktion / avdelningschef | D37: 1.2 | E37: 1:e AD, Kostymör, Ljudmästare, Colorist, Manusförfattare, Skådespelare i återkommande biroll
B38: C | C38: Operativt bidrag / stödfunktion | D38: 1 | E38: PA, Grip, Gaffer, Rekvisitör, övrig crew, Statist / enstaka replikroll

Sheet Egeninsats & Poäng
B2: EGENINSATS & POÄNGREGISTER
B3: Kopplar till SFI-mallens Egeninsats-flik · Blå text = fyll i manuellt · Svart text = formel
B4: # | C4: Namn | D4: Roll / Befattning | E4: Klass | F4: Fas | G4: Dagar | H4: Cash Fee (SEK/dag) | I4: Markn.pris (SEK/dag) | J4: Deferred Fee (SEK) | K4: Grundp./dag (från inst.) | L4: Klassmult. (från inst.) | M4: Poäng (beräknat) | N4: Anteckningar
B5: 1 | C5: Anna Lindström | D5: Regissör | E5: A | F5: F1 | G5: 15 | H5: 0 | I5: 2500 | J5: =(I5-H5)*G5 | K5: =IFERROR(INDEX(Projektinställningar!$G$24:$G$31,MATCH(F5,Projektinställningar!$B$24:$B$31,0)),"?") | L5: =IFERROR(INDEX(Projektinställningar!$D$36:$D$38,MATCH(E5,Projektinställningar!$B$36:$B$38,0)),"?") | M5: =IF(AND(ISNUMBER(K5),ISNUMBER(L5)),G5*K5*L5,"")
B6: 2 | C6: Anna Lindström | D6: Regissör | E6: A | F6: F4 | G6: 40 | H6: 1200 | I6: 2500 | J6: =(I6-H6)*G6 | K6: =IFERROR(INDEX(Projektinställningar!$G$24:$G$31,MATCH(F6,Projektinställningar!$B$24:$B$31,0)),"?") | L6: =IFERROR(INDEX(Projektinställningar!$D$36:$D$38,MATCH(E6,Projektinställningar!$B$36:$B$38,0)),"?") | M6: =IF(AND(ISNUMBER(K6),ISNUMBER(L6)),G6*K6*L6,"")
B7: 3 | C7: Erik Johansson | D7: DOP | E7: A | F7: F4 | G7: 30 | H7: 1000 | I7: 2000 | J7: =(I7-H7)*G7 | K7: =IFERROR(INDEX(Projektinställningar!$G$24:$G$31,MATCH(F7,Projektinställningar!$B$24:$B$31,0)),"?") | L7: =IFERROR(INDEX(Projektinställningar!$D$36:$D$38,MATCH(E7,Projektinställningar!$B$36:$B$38,0)),"?") | M7: =IF(AND(ISNUMBER(K7),ISNUMBER(L7)),G7*K7*L7,"")
B8: 4 | C8: Sara Nilsson | D8: 1:e AD | E8: B | F8: F4 | G8: 30 | H8: 900 | I8: 1800 | J8: =(I8-H8)*G8 | K8: =IFERROR(INDEX(Projektinställningar!$G$24:$G$31,MATCH(F8,Projektinställningar!$B$24:$B$31,0)),"?") | L8: =IFERROR(INDEX(Projektinställningar!$D$36:$D$38,MATCH(E8,Projektinställningar!$B$36:$B$38,0)),"?") | M8: =IF(AND(ISNUMBER(K8),ISNUMBER(L8)),G8*K8*L8,"")
B9: 5 | C9: Per Gustafsson | D9: Producent | E9: A | F9: F1 | G9: 20 | H9: 0 | I9: 2500 | J9: =(I9-H9)*G9 | K9: =IFERROR(INDEX(Projektinställningar!$G$24:$G$31,MATCH(F9,Projektinställningar!$B$24:$B$31,0)),"?") | L9: =IFERROR(INDEX(Projektinställningar!$D$36:$D$38,MATCH(E9,Projektinställningar!$B$36:$B$38,0)),"?") | M9: =IF(AND(ISNUMBER(K9),ISNUMBER(L9)),G9*K9*L9,"")
B10: 6 | C10: Per Gustafsson | D10: Producent | E10: A | F10: F4 | G10: 40 | H10: 1200 | I10: 2500 | J10: =(I10-H10)*G10 | K10: =IFERROR(INDEX(Projektinställningar!$G$24:$G$31,MATCH(F10,Projektinställningar!$B$24:$B$31,0)),"?") | L10: =IFERROR(INDEX(Projektinställningar!$D$36:$D$38,MATCH(E10,Projektinställningar!$B$36:$B$38,0)),"?") | M10: =IF(AND(ISNUMBER(K10),ISNUMBER(L10)),G10*K10*L10,"")
B11: 7 | C11: Lena Berg | D11: Scenograf | E11: A | F11: F4 | G11: 25 | H11: 1000 | I11: 2000 | J11: =(I11-H11)*G11 | K11: =IFERROR(INDEX(Projektinställningar!$G$24:$G$31,MATCH(F11,Projektinställningar!$B$24:$B$31,0)),"?") | L11: =IFERROR(INDEX(Projektinställningar!$D$36:$D$38,MATCH(E11,Projektinställningar!$B$36:$B$38,0)),"?") | M11: =IF(AND(ISNUMBER(K11),ISNUMBER(L11)),G11*K11*L11,"")
B12: 8 | C12: Johan Ek | D12: Klippare | E12: A | F12: F6 | G12: 30 | H12: 900 | I12: 2000 | J12: =(I12-H12)*G12 | K12: =IFERROR(INDEX(Projektinställningar!$G$24:$G$31,MATCH(F12,Projektinställningar!$B$24:$B$31,0)),"?") | L12: =IFERROR(INDEX(Projektinställningar!$D$36:$D$38,MATCH(E12,Projektinställningar!$B$36:$B$38,0)),"?") | M12: =IF(AND(ISNUMBER(K12),ISNUMBER(L12)),G12*K12*L12,"")
B13: 9 | C13: Maria Svensson | D13: Kostymör | E13: B | F13: F4 | G13: 20 | H13: 800 | I13: 1600 | J13: =(I13-H13)*G13 | K13: =IFERROR(INDEX(Projektinställningar!$G$24:$G$31,MATCH(F13,Projektinställningar!$B$24:$B$31,0)),"?") | L13: =IFERROR(INDEX(Projektinställningar!$D$36:$D$38,MATCH(E13,Projektinställningar!$B$36:$B$38,0)),"?") | M13: =IF(AND(ISNUMBER(K13),ISNUMBER(L13)),G13*K13*L13,"")
B14: 10 | C14: Kalle Strand | D14: PA | E14: C | F14: F4 | G14: 25 | H14: 600 | I14: 600 | J14: =(I14-H14)*G14 | K14: =IFERROR(INDEX(Projektinställningar!$G$24:$G$31,MATCH(F14,Projektinställningar!$B$24:$B$31,0)),"?") | L14: =IFERROR(INDEX(Projektinställningar!$D$36:$D$38,MATCH(E14,Projektinställningar!$B$36:$B$38,0)),"?") | M14: =IF(AND(ISNUMBER(K14),ISNUMBER(L14)),G14*K14*L14,"")
B15: 11 | C15: Elin Holm | D15: Skådespelare (huvudroll) | E15: A | F15: F4 | G15: 20 | H15: 900 | I15: 2200 | J15: =(I15-H15)*G15 | K15: =IFERROR(INDEX(Projektinställningar!$G$24:$G$31,MATCH(F15,Projektinställningar!$B$24:$B$31,0)),"?") | L15: =IFERROR(INDEX(Projektinställningar!$D$36:$D$38,MATCH(E15,Projektinställningar!$B$36:$B$38,0)),"?") | M15: =IF(AND(ISNUMBER(K15),ISNUMBER(L15)),G15*K15*L15,"")
B16: SUMMERING | J16: =SUM(J5:J15) | M16: =SUM(M5:M15)
B17: 12 | J17: =(I17-H17)*G17 | K17: =IFERROR(INDEX(Projektinställningar!$G$24:$G$31,MATCH(F17,Projektinställningar!$B$24:$B$31,0)),"") | L17: =IFERROR(INDEX(Projektinställningar!$D$36:$D$38,MATCH(E17,Projektinställningar!$B$36:$B$38,0)),"") | M17: =IF(AND(ISNUMBER(K17),ISNUMBER(L17)),G17*K17*L17,"")
B18: 13 | J18: =(I18-H18)*G18 | K18: =IFERROR(INDEX(Projektinställningar!$G$24:$G$31,MATCH(F18,Projektinställningar!$B$24:$B$31,0)),"") | L18: =IFERROR(INDEX(Projektinställningar!$D$36:$D$38,MATCH(E18,Projektinställningar!$B$36:$B$38,0)),"") | M18: =IF(AND(ISNUMBER(K18),ISNUMBER(L18)),G18*K18*L18,"")
B19: 14 | J19: =(I19-H19)*G19 | K19: =IFERROR(INDEX(Projektinställningar!$G$24:$G$31,MATCH(F19,Projektinställningar!$B$24:$B$31,0)),"") | L19: =IFERROR(INDEX(Projektinställningar!$D$36:$D$38,MATCH(E19,Projektinställningar!$B$36:$B$38,0)),"") | M19: =IF(AND(ISNUMBER(K19),ISNUMBER(L19)),G19*K19*L19,"")
B20: 15 | J20: =(I20-H20)*G20 | K20: =IFERROR(INDEX(Projektinställningar!$G$24:$G$31,MATCH(F20,Projektinställningar!$B$24:$B$31,0)),"") | L20: =IFERROR(INDEX(Projektinställningar!$D$36:$D$38,MATCH(E20,Projektinställningar!$B$36:$B$38,0)),"") | M20: =IF(AND(ISNUMBER(K20),ISNUMBER(L20)),G20*K20*L20,"")
B21: 16 | J21: =(I21-H21)*G21 | K21: =IFERROR(INDEX(Projektinställningar!$G$24:$G$31,MATCH(F21,Projektinställningar!$B$24:$B$31,0)),"") | L21: =IFERROR(INDEX(Projektinställningar!$D$36:$D$38,MATCH(E21,Projektinställningar!$B$36:$B$38,0)),"") | M21: =IF(AND(ISNUMBER(K21),ISNUMBER(L21)),G21*K21*L21,"")
B22: 17 | J22: =(I22-H22)*G22 | K22: =IFERROR(INDEX(Projektinställningar!$G$24:$G$31,MATCH(F22,Projektinställningar!$B$24:$B$31,0)),"") | L22: =IFERROR(INDEX(Projektinställningar!$D$36:$D$38,MATCH(E22,Projektinställningar!$B$36:$B$38,0)),"") | M22: =IF(AND(ISNUMBER(K22),ISNUMBER(L22)),G22*K22*L22,"")
B23: 18 | J23: =(I23-H23)*G23 | K23: =IFERROR(INDEX(Projektinställningar!$G$24:$G$31,MATCH(F23,Projektinställningar!$B$24:$B$31,0)),"") | L23: =IFERROR(INDEX(Projektinställningar!$D$36:$D$38,MATCH(E23,Projektinställningar!$B$36:$B$38,0)),"") | M23: =IF(AND(ISNUMBER(K23),ISNUMBER(L23)),G23*K23*L23,"")
B24: 19 | J24: =(I24-H24)*G24 | K24: =IFERROR(INDEX(Projektinställningar!$G$24:$G$31,MATCH(F24,Projektinställningar!$B$24:$B$31,0)),"") | L24: =IFERROR(INDEX(Projektinställningar!$D$36:$D$38,MATCH(E24,Projektinställningar!$B$36:$B$38,0)),"") | M24: =IF(AND(ISNUMBER(K24),ISNUMBER(L24)),G24*K24*L24,"")
B25: 20 | J25: =(I25-H25)*G25 | K25: =IFERROR(INDEX(Projektinställningar!$G$24:$G$31,MATCH(F25,Projektinställningar!$B$24:$B$31,0)),"") | L25: =IFERROR(INDEX(Projektinställningar!$D$36:$D$38,MATCH(E25,Projektinställningar!$B$36:$B$38,0)),"") | M25: =IF(AND(ISNUMBER(K25),ISNUMBER(L25)),G25*K25*L25,"")
B26: 21 | J26: =(I26-H26)*G26 | K26: =IFERROR(INDEX(Projektinställningar!$G$24:$G$31,MATCH(F26,Projektinställningar!$B$24:$B$31,0)),"") | L26: =IFERROR(INDEX(Projektinställningar!$D$36:$D$38,MATCH(E26,Projektinställningar!$B$36:$B$38,0)),"") | M26: =IF(AND(ISNUMBER(K26),ISNUMBER(L26)),G26*K26*L26,"")
B27: 22 | J27: =(I27-H27)*G27 | K27: =IFERROR(INDEX(Projektinställningar!$G$24:$G$31,MATCH(F27,Projektinställningar!$B$24:$B$31,0)),"") | L27: =IFERROR(INDEX(Projektinställningar!$D$36:$D$38,MATCH(E27,Projektinställningar!$B$36:$B$38,0)),"") | M27: =IF(AND(ISNUMBER(K27),ISNUMBER(L27)),G27*K27*L27,"")
B28: 23 | J28: =(I28-H28)*G28 | K28: =IFERROR(INDEX(Projektinställningar!$G$24:$G$31,MATCH(F28,Projektinställningar!$B$24:$B$31,0)),"") | L28: =IFERROR(INDEX(Projektinställningar!$D$36:$D$38,MATCH(E28,Projektinställningar!$B$36:$B$38,0)),"") | M28: =IF(AND(ISNUMBER(K28),ISNUMBER(L28)),G28*K28*L28,"")
... B31: 26 | J31: =(I31-H31)*G31 | K31: =IFERROR(INDEX(Projektinställningar!$G$24:$G$31,MATCH(F31,Projektinställningar!$B$24:$B$31,0)),"") | L31: =IFERROR(INDEX(Projektinställningar!$D$36:$D$38,MATCH(E31,Projektinställningar!$B$36:$B$38,0)),"") | M31: =IF(AND(ISNUMBER(K31),ISNUMBER(L31)),G31*K31*L31,"")

Sheet Equity Dashboard
B2: EQUITY DASHBOARD
B3: Automatisk sammanställning — uppdateras när Egeninsats & Poäng fylls i
B5: ÄGARANDELAR PER PERSON
B6: Namn | C6: Roll | D6: Total deferred (SEK) | E6: Totala poäng | F6: Ägarandel (%) | G6: Status
B7: Anna Lindström | C7: Regissör | D7: =SUMIF('Egeninsats & Poäng'!C:C,B7,'Egeninsats & Poäng'!J:J) | E7: =SUMIF('Egeninsats & Poäng'!C:C,B7,'Egeninsats & Poäng'!M:M) | F7: =IFERROR(E7/SUM('Egeninsats & Poäng'!M:M),0) | G7: Aktiv
B8: Per Gustafsson | C8: Producent | D8: =SUMIF('Egeninsats & Poäng'!C:C,B8,'Egeninsats & Poäng'!J:J) | E8: =SUMIF('Egeninsats & Poäng'!C:C,B8,'Egeninsats & Poäng'!M:M) | F8: =IFERROR(E8/SUM('Egeninsats & Poäng'!M:M),0) | G8: Aktiv
B9: Erik Johansson | C9: DOP | D9: =SUMIF('Egeninsats & Poäng'!C:C,B9,'Egeninsats & Poäng'!J:J) | E9: =SUMIF('Egeninsats & Poäng'!C:C,B9,'Egeninsats & Poäng'!M:M) | F9: =IFERROR(E9/SUM('Egeninsats & Poäng'!M:M),0) | G9: Aktiv
B10: Sara Nilsson | C10: 1:e AD | D10: =SUMIF('Egeninsats & Poäng'!C:C,B10,'Egeninsats & Poäng'!J:J) | E10: =SUMIF('Egeninsats & Poäng'!C:C,B10,'Egeninsats & Poäng'!M:M) | F10: =IFERROR(E10/SUM('Egeninsats & Poäng'!M:M),0) | G10: Aktiv
B11: Lena Berg | C11: Scenograf | D11: =SUMIF('Egeninsats & Poäng'!C:C,B11,'Egeninsats & Poäng'!J:J) | E11: =SUMIF('Egeninsats & Poäng'!C:C,B11,'Egeninsats & Poäng'!M:M) | F11: =IFERROR(E11/SUM('Egeninsats & Poäng'!M:M),0) | G11: Aktiv
B12: Johan Ek | C12: Klippare | D12: =SUMIF('Egeninsats & Poäng'!C:C,B12,'Egeninsats & Poäng'!J:J) | E12: =SUMIF('Egeninsats & Poäng'!C:C,B12,'Egeninsats & Poäng'!M:M) | F12: =IFERROR(E12/SUM('Egeninsats & Poäng'!M:M),0) | G12: Aktiv
B13: Maria Svensson | C13: Kostymör | D13: =SUMIF('Egeninsats & Poäng'!C:C,B13,'Egeninsats & Poäng'!J:J) | E13: =SUMIF('Egeninsats & Poäng'!C:C,B13,'Egeninsats & Poäng'!M:M) | F13: =IFERROR(E13/SUM('Egeninsats & Poäng'!M:M),0) | G13: Aktiv
B14: Kalle Strand | C14: PA | D14: =SUMIF('Egeninsats & Poäng'!C:C,B14,'Egeninsats & Poäng'!J:J) | E14: =SUMIF('Egeninsats & Poäng'!C:C,B14,'Egeninsats & Poäng'!M:M) | F14: =IFERROR(E14/SUM('Egeninsats & Poäng'!M:M),0) | G14: Aktiv
B15: TOTALT | D15: =SUM(D7:D14) | E15: =SUM(E7:E14) | F15: =SUM(F7:F14)

Sheet Fasbudget
B2: FASBUDGET — HELHETSBUDGET PER PRODUKTIONSFAS
B3: Knyter an till SFI-posternas struktur (01–26). Varje cell är manuell inmatning eller länk från detaljbudget.
B5: SFI-post | C5: Benämning | D5: F1 Development | E5: F2 Pre-prod | F5: F3 Pilot | G5: F4 Prod Fas 1 | H5: F5 Prod Fas 2 | I5: F6 Post | J5: F7 Lansering | K5: TOTALT
B6: 01 | C6: MANUS & FÖRARBETE
B7: 01.1 | C7: Manusarvode | K7: =SUM(D7:J7)
B8: 01.2 | C8: Manuskonsultation | K8: =SUM(D8:J8)
B9: 01.3 | C9: Research | K9: =SUM(D9:J9)
B10: 02 | C10: RÄTTIGHETER
B11: 02.1 | C11: Optionsarvode | K11: =SUM(D11:J11)
B12: 03 | C12: PRODUCENT & PROJEKTLEDNING
B13: 03.1 | C13: Producentarvode | K13: =SUM(D13:J13)
B14: 03.2 | C14: Linjeprodukton | K14: =SUM(D14:J14)
B15: 04 | C15: REGI
B16: 04.1 | C16: Regiarvode | K16: =SUM(D16:J16)
B17: 04.2 | C17: Regiassistans | K17: =SUM(D17:J17)
B18: 05 | C18: SKÅDESPELERI
B19: 05.1 | C19: Huvudroller | K19: =SUM(D19:J19)
B20: 05.2 | C20: Biroller | K20: =SUM(D20:J20)
B21: 06 | C21: FOTO & KAMERATEKNIK
B22: 06.1 | C22: DOP-arvode | K22: =SUM(D22:J22)
B23: 06.2 | C23: Kamerautrustning | K23: =SUM(D23:J23)
B24: 07 | C24: LJUS & ELEKTRISK
B25: 08 | C25: LJUD
B26: 09 | C26: SCENOGRAFI & REKVISITA
B27: 10 | C27: KOSTYM & MASK
B28: 11 | C28: LOCATIONS & STUDIOR
B29: 12 | C29: TRANSPORT
B30: 13 | C30: CATERING & LOGI
B31: 14 | C31: INSPELNINGSLEDNING
B32: 15 | C32: POSTPRODUKTION — BILD
B33: 15.1 | C33: Klippning | K33: =SUM(D33:J33)
B34: 15.2 | C34: VFX & DI | K34: =SUM(D34:J34)
B35: 16 | C35: POSTPRODUKTION — LJUD
B36: 16.1 | C36: Ljuddesign & mix | K36: =SUM(D36:J36)
B37: 17 | C37: MUSIK
B38: 18 | C38: TEXTNING & DUBBNING
B39: 19 | C39: MASTERING & LEVERANS
B40: 20 | C40: FESTIVALER & PROMOTION
B41: 21 | C41: FÖRSÄKRINGAR
B42: 22 | C42: ADMINISTRATION & OVERHEAD
...

Sheet Waterfall Simulering
B2: WATERFALL — RECOUPMENT SIMULERING
B3: Simulera utfall vid tre scenarier. Blå celler = inmatning.
D5: Scenario A (Litet utfall) | E5: Scenario B (Mellanstort) | F5: Scenario C (Stort utfall)
B6: INPARAMETRAR (fyll i)
B7: Bruttointäkt (SEK) | D7: 500000 | E7: 2000000 | F7: 8000000
B8: Distributionsavgift (%) | D8: 0.25 | E8: 0.25 | F8: 0.2
B9: Kontant budget / negativkostnad (SEK)
B10: Extern finansiärs kapital (SEK) | D10: 0 | E10: 500000 | F10: 1000000
B11: Finansiärs avkastningsmultiplikator | D11: 1 | E11: 1.2 | F11: 1.2
B12: Total deferred fee pool (SEK, från Dashboard)
B14: WATERFALL-BERÄKNING
B15: Steg 1 Bruttointäkt | D15: =D7 | E15: =E7 | F15: =F7
B16: Steg 1b — Distributionsavgift (–) | D16: =-D7*D8 | E16: =-E7*E8 | F16: =-F7*F8
B17: NETTO EFTER DISTRIBUTION | D17: =D15+D16 | E17: =E15+E16 | F17: =F15+F16
B18: Steg 2 — Extern finansiärs recoupment (–) | D18: =-MIN(D10*D11,D17) | E18: =-MIN(E10*E11,E17) | F18: =-MIN(F10*F11,F17)
B19: NETTO EFTER FINANSIÄR | D19: =D17+D18 | E19: =E17+E18 | F19: =F17+F18
B20: Steg 3 — Deferred fee pool (–) | D20: =-MIN(D12,MAX(0,D19)) | E20: =-MIN(E12,MAX(0,E19)) | F20: =-MIN(F12,MAX(0,F19))
B21: NETTO EFTER DEFERRED | D21: =MAX(0,D19+D20) | E21: =MAX(0,E19+E20) | F21: =MAX(0,F19+F20)
B22: Steg 4 Crew equity-pool (50% av netto) | D22: =D21*0.5 | E22: =E21*0.5 | F22: =F21*0.5
B23: Steg 5 Finansiärspool (50% av netto) | D23: =D21*0.5 | E23: =E21*0.5 | F23: =F21*0.5
B24: TOTALT DISTRIBUERAT | D24: =D22+D23 | E24: =E22+E23 | F24: =F22+F23
B27: * Crew-poolen fördelas sedan per person enligt ägarandel (%) från Equity Dashboard. Länk till per-person-utdrag byggs i portal (steg 2).

Sheet Personutdrag
B2: =Projektinställningar!C5
B3: Ägarandelsutdrag — Samägande filmproduktion
B6: Anna Lindström
B7: Regissör
B9: TOTALT DEFERRED (SEK) | E9: TOTALA POÄNG | H9: ÄGARANDEL
B10: ='Equity Dashboard'!D7 | E10: ='Equity Dashboard'!E7 | H10: ='Equity Dashboard'!F7
B12: POÄNGHISTORIK PER FAS
B13: Fas | C13: Benämning | D13: Dagar | E13: Cash Fee/dag | F13: Markn.pris/dag | G13: Deferred (SEK) | H13: Grundp./dag | I13: Klassmult. | J13: Poäng | K13: Andel av egna
B14: F1 | C14: =Projektinställningar!C24 | D14: =SUMIFS('Egeninsats & Poäng'!G:G,'Egeninsats & Poäng'!C:C,"Anna Lindström",'Egeninsats & Poäng'!F:F,"F1") | E14: =IFERROR(SUMIFS('Egeninsats & Poäng'!H:H,'Egeninsats & Poäng'!C:C,"Anna Lindström",'Egeninsats & Poäng'!F:F,"F1")/SUMIFS('Egeninsats & Poäng'!G:G,'Egeninsats & Poäng'!C:C,"Anna Lindström",'Egeninsats & Poäng'!F:F,"F1"),"") | F14: =IFERROR(SUMIFS('Egeninsats & Poäng'!I:I,'Egeninsats & Poäng'!C:C,"Anna Lindström",'Egeninsats & Poäng'!F:F,"F1")/SUMIFS('Egeninsats & Poäng'!G:G,'Egeninsats & Poäng'!C:C,"Anna Lindström",'Egeninsats & Poäng'!F:F,"F1"),"") | G14: =SUMIFS('Egeninsats & Poäng'!J:J,'Egeninsats & Poäng'!C:C,"Anna Lindström",'Egeninsats & Poäng'!F:F,"F1") | H14: =IFERROR(SUMIFS('Egeninsats & Poäng'!K:K,'Egeninsats & Poäng'!C:C,"Anna Lindström",'Egeninsats & Poäng'!F:F,"F1")/SUMIFS('Egeninsats & Poäng'!G:G,'Egeninsats & Poäng'!C:C,"Anna Lindström",'Egeninsats & Poäng'!F:F,"F1"),"") | I14: =IFERROR(SUMIFS('Egeninsats & Poäng'!L:L,'Egeninsats & Poäng'!C:C,"Anna Lindström",'Egeninsats & Poäng'!F:F,"F1")/SUMIFS('Egeninsats & Poäng'!G:G,'Egeninsats & Poäng'!C:C,"Anna Lindström",'Egeninsats & Poäng'!F:F,"F1"),"") | J14: =SUMIFS('Egeninsats & Poäng'!M:M,'Egeninsats & Poäng'!C:C,"Anna Lindström",'Egeninsats & Poäng'!F:F,"F1") | K14: =IFERROR(J14/'Equity Dashboard'!E7,"")
B15: F2 | C15: =Projektinställningar!C25 | D15: =SUMIFS('Egeninsats & Poäng'!G:G,'Egeninsats & Poäng'!C:C,"Anna Lindström",'Egeninsats & Poäng'!F:F,"F2") | E15: =IFERROR(SUMIFS('Egeninsats & Poäng'!H:H,'Egeninsats & Poäng'!C:C,"Anna Lindström",'Egeninsats & Poäng'!F:F,"F2")/SUMIFS('Egeninsats & Poäng'!G:G,'Egeninsats & Poäng'!C:C,"Anna Lindström",'Egeninsats & Poäng'!F:F,"F2"),"") | F15: =IFERROR(SUMIFS('Egeninsats & Poäng'!I:I,'Egeninsats & Poäng'!C:C,"Anna Lindström",'Egeninsats & Poäng'!F:F,"F2")/SUMIFS('Egeninsats & Poäng'!G:G,'Egeninsats & Poäng'!C:C,"Anna Lindström",'Egeninsats & Poäng'!F:F,"F2"),"") | G15: =SUMIFS('Egeninsats & Poäng'!J:J,'Egeninsats & Poäng'!C:C,"Anna Lindström",'Egeninsats & Poäng'!F:F,"F2") | H15: =IFERROR(SUMIFS('Egeninsats & Poäng'!K:K,'Egeninsats & Poäng'!C:C,"Anna Lindström",'Egeninsats & Poäng'!F:F,"F2")/SUMIFS('Egeninsats & Poäng'!G:G,'Egeninsats & Poäng'!C:C,"Anna Lindström",'Egeninsats & Poäng'!F:F,"F2"),"") | I15: =IFERROR(SUMIFS('Egeninsats & Poäng'!L:L,'Egeninsats & Poäng'!C:C,"Anna Lindström",'Egeninsats & Poäng'!F:F,"F2")/SUMIFS('Egeninsats & Poäng'!G:G,'Egeninsats & Poäng'!C:C,"Anna Lindström",'Egeninsats & Poäng'!F:F,"F2"),"") | J15: =SUMIFS('Egeninsats & Poäng'!M:M,'Egeninsats & Poäng'!C:C,"Anna Lindström",'Egeninsats & Poäng'!F:F,"F2") | K15: =IFERROR(J15/'Equity Dashboard'!E7,"")
B16: F3 | C16: =Projektinställningar!C26 | D16: =SUMIFS('Egeninsats & Poäng'!G:G,'Egeninsats & Poäng'!C:C,"Anna Lindström",'Egeninsats & Poäng'!F:F,"F3") | E16: =IFERROR(SUMIFS('Egeninsats & Poäng'!H:H,'Egeninsats & Poäng'!C:C,"Anna Lindström",'Egeninsats & Poäng'!F:F,"F3")/SUMIFS('Egeninsats & Poäng'!G:G,'Egeninsats & Poäng'!C:C,"Anna Lindström",'Egeninsats & Poäng'!F:F,"F3"),"") | F16: =IFERROR(SUMIFS('Egeninsats & Poäng'!I:I,'Egeninsats & Poäng'!C:C,"Anna Lindström",'Egeninsats & Poäng'!F:F,"F3")/SUMIFS('Egeninsats & Poäng'!G:G,'Egeninsats & Poäng'!C:C,"Anna Lindström",'Egeninsats & Poäng'!F:F,"F3"),"") | G16: =SUMIFS('Egeninsats & Poäng'!J:J,'Egeninsats & Poäng'!C:C,"Anna Lindström",'Egeninsats & Poäng'!F:F,"F3") | H16: =IFERROR(SUMIFS('Egeninsats & Poäng'!K:K,'Egeninsats & Poäng'!C:C,"Anna Lindström",'Egeninsats & Poäng'!F:F,"F3")/SUMIFS('Egeninsats & Poäng'!G:G,'Egeninsats & Poäng'!C:C,"Anna Lindström",'Egeninsats & Poäng'!F:F,"F3"),"") | I16: =IFERROR(SUMIFS('Egeninsats & Poäng'!L:L,'Egeninsats & Poäng'!C:C,"Anna Lindström",'Egeninsats & Poäng'!F:F,"F3")/SUMIFS('Egeninsats & Poäng'!G:G,'Egeninsats & Poäng'!C:C,"Anna Lindström",'Egeninsats & Poäng'!F:F,"F3"),"") | J16: =SUMIFS('Egeninsats & Poäng'!M:M,'Egeninsats & Poäng'!C:C,"Anna Lindström",'Egeninsats & Poäng'!F:F,"F3") | K16: =IFERROR(J16/'Equity Dashboard'!E7,"")
B17: F4 | C17: =Projektinställningar!C27 | D17: =SUMIFS('Egeninsats & Poäng'!G:G,'Egeninsats & Poäng'!C:C,"Anna Lindström",'Egeninsats & Poäng'!F:F,"F4") | E17: =IFERROR(SUMIFS('Egeninsats & Poäng'!H:H,'Egeninsats & Poäng'!C:C,"Anna Lindström",'Egeninsats & Poäng'!F:F,"F4")/SUMIFS('Egeninsats & Poäng'!G:G,'Egeninsats & Poäng'!C:C,"Anna Lindström",'Egeninsats & Poäng'!F:F,"F4"),"") | F17: =IFERROR(SUMIFS('Egeninsats & Poäng'!I:I,'Egeninsats & Poäng'!C:C,"Anna Lindström",'Egeninsats & Poäng'!F:F,"F4")/SUMIFS('Egeninsats & Poäng'!G:G,'Egeninsats & Poäng'!C:C,"Anna Lindström",'Egeninsats & Poäng'!F:F,"F4"),"") | G17: =SUMIFS('Egeninsats & Poäng'!J:J,'Egeninsats & Poäng'!C:C,"Anna Lindström",'Egeninsats & Poäng'!F:F,"F4") | H17: =IFERROR(SUMIFS('Egeninsats & Poäng'!K:K,'Egeninsats & Poäng'!C:C,"Anna Lindström",'Egeninsats & Poäng'!F:F,"F4")/SUMIFS('Egeninsats & Poäng'!G:G,'Egeninsats & Poäng'!C:C,"Anna Lindström",'Egeninsats & Poäng'!F:F,"F4"),"") | I17: =IFERROR(SUMIFS('Egeninsats & Poäng'!L:L,'Egeninsats & Poäng'!C:C,"Anna Lindström",'Egeninsats & Poäng'!F:F,"F4")/SUMIFS('Egeninsats & Poäng'!G:G,'Egeninsats & Poäng'!C:C,"Anna Lindström",'Egeninsats & Poäng'!F:F,"F4"),"") | J17: =SUMIFS('Egeninsats & Poäng'!M:M,'Egeninsats & Poäng'!C:C,"Anna Lindström",'Egeninsats & Poäng'!F:F,"F4") | K17: =IFERROR(J17/'Equity Dashboard'!E7,"")
B18: F5 | C18: =Projektinställningar!C28 | D18: =SUMIFS('Egeninsats & Poäng'!G:G,'Egeninsats & Poäng'!C:C,"Anna Lindström",'Egeninsats & Poäng'!F:F,"F5") | E18: =IFERROR(SUMIFS('Egeninsats & Poäng'!H:H,'Egeninsats & Poäng'!C:C,"Anna Lindström",'Egeninsats & Poäng'!F:F,"F5")/SUMIFS('Egeninsats & Poäng'!G:G,'Egeninsats & Poäng'!C:C,"Anna Lindström",'Egeninsats & Poäng'!F:F,"F5"),"") | F18: =IFERROR(SUMIFS('Egeninsats & Poäng'!I:I,'Egeninsats & Poäng'!C:C,"Anna Lindström",'Egeninsats & Poäng'!F:F,"F5")/SUMIFS('Egeninsats & Poäng'!G:G,'Egeninsats & Poäng'!C:C,"Anna Lindström",'Egeninsats & Poäng'!F:F,"F5"),"") | G18: =SUMIFS('Egeninsats & Poäng'!J:J,'Egeninsats & Poäng'!C:C,"Anna Lindström",'Egeninsats & Poäng'!F:F,"F5") | H18: =IFERROR(SUMIFS('Egeninsats & Poäng'!K:K,'Egeninsats & Poäng'!C:C,"Anna Lindström",'Egeninsats & Poäng'!F:F,"F5")/SUMIFS('Egeninsats & Poäng'!G:G,'Egeninsats & Poäng'!C:C,"Anna Lindström",'Egeninsats & Poäng'!F:F,"F5"),"") | I18: =IFERROR(SUMIFS('Egeninsats & Poäng'!L:L,'Egeninsats & Poäng'!C:C,"Anna Lindström",'Egeninsats & Poäng'!F:F,"F5")/SUMIFS('Egeninsats & Poäng'!G:G,'Egeninsats & Poäng'!C:C,"Anna Lindström",'Egeninsats & Poäng'!F:F,"F5"),"") | J18: =SUMIFS('Egeninsats & Poäng'!M:M,'Egeninsats & Poäng'!C:C,"Anna Lindström",'Egeninsats & Poäng'!F:F,"F5") | K18: =IFERROR(J18/'Equity Dashboard'!E7,"")
B19: F6 | C19: =Projektinställningar!C29 | D19: =SUMIFS('Egeninsats & Poäng'!G:G,'Egeninsats & Poäng'!C:C,"Anna Lindström",'Egeninsats & Poäng'!F:F,"F6") | E19: =IFERROR(SUMIFS('Egeninsats & Poäng'!H:H,'Egeninsats & Poäng'!C:C,"Anna Lindström",'Egeninsats & Poäng'!F:F,"F6")/SUMIFS('Egeninsats & Poäng'!G:G,'Egeninsats & Poäng'!C:C,"Anna Lindström",'Egeninsats & Poäng'!F:F,"F6"),"") | F19: =IFERROR(SUMIFS('Egeninsats & Poäng'!I:I,'Egeninsats & Poäng'!C:C,"Anna Lindström",'Egeninsats & Poäng'!F:F,"F6")/SUMIFS('Egeninsats & Poäng'!G:G,'Egeninsats & Poäng'!C:C,"Anna Lindström",'Egeninsats & Poäng'!F:F,"F6"),"") | G19: =SUMIFS('Egeninsats & Poäng'!J:J,'Egeninsats & Poäng'!C:C,"Anna Lindström",'Egeninsats & Poäng'!F:F,"F6") | H19: =IFERROR(SUMIFS('Egeninsats & Poäng'!K:K,'Egeninsats & Poäng'!C:C,"Anna Lindström",'Egeninsats & Poäng'!F:F,"F6")/SUMIFS('Egeninsats & Poäng'!G:G,'Egeninsats & Poäng'!C:C,"Anna Lindström",'Egeninsats & Poäng'!F:F,"F6"),"") | I19: =IFERROR(SUMIFS('Egeninsats & Poäng'!L:L,'Egeninsats & Poäng'!C:C,"Anna Lindström",'Egeninsats & Poäng'!F:F,"F6")/SUMIFS('Egeninsats & Poäng'!G:G,'Egeninsats & Poäng'!C:C,"Anna Lindström",'Egeninsats & Poäng'!F:F,"F6"),"") | J19: =SUMIFS('Egeninsats & Poäng'!M:M,'Egeninsats & Poäng'!C:C,"Anna Lindström",'Egeninsats & Poäng'!F:F,"F6") | K19: =IFERROR(J19/'Equity Dashboard'!E7,"")
B20: F7 | C20: =Projektinställningar!C30 | D20: =SUMIFS('Egeninsats & Poäng'!G:G,'Egeninsats & Poäng'!C:C,"Anna Lindström",'Egeninsats & Poäng'!F:F,"F7") | E20: =IFERROR(SUMIFS('Egeninsats & Poäng'!H:H,'Egeninsats & Poäng'!C:C,"Anna Lindström",'Egeninsats & Poäng'!F:F,"F7")/SUMIFS('Egeninsats & Poäng'!G:G,'Egeninsats & Poäng'!C:C,"Anna Lindström",'Egeninsats & Poäng'!F:F,"F7"),"") | F20: =IFERROR(SUMIFS('Egeninsats & Poäng'!I:I,'Egeninsats & Poäng'!C:C,"Anna Lindström",'Egeninsats & Poäng'!F:F,"F7")/SUMIFS('Egeninsats & Poäng'!G:G,'Egeninsats & Poäng'!C:C,"Anna Lindström",'Egeninsats & Poäng'!F:F,"F7"),"") | G20: =SUMIFS('Egeninsats & Poäng'!J:J,'Egeninsats & Poäng'!C:C,"Anna Lindström",'Egeninsats & Poäng'!F:F,"F7") | H20: =IFERROR(SUMIFS('Egeninsats & Poäng'!K:K,'Egeninsats & Poäng'!C:C,"Anna Lindström",'Egeninsats & Poäng'!F:F,"F7")/SUMIFS('Egeninsats & Poäng'!G:G,'Egeninsats & Poäng'!C:C,"Anna Lindström",'Egeninsats & Poäng'!F:F,"F7"),"") | I20: =IFERROR(SUMIFS('Egeninsats & Poäng'!L:L,'Egeninsats & Poäng'!C:C,"Anna Lindström",'Egeninsats & Poäng'!F:F,"F7")/SUMIFS('Egeninsats & Poäng'!G:G,'Egeninsats & Poäng'!C:C,"Anna Lindström",'Egeninsats & Poäng'!F:F,"F7"),"") | J20: =SUMIFS('Egeninsats & Poäng'!M:M,'Egeninsats & Poäng'!C:C,"Anna Lindström",'Egeninsats & Poäng'!F:F,"F7") | K20: =IFERROR(J20/'Equity Dashboard'!E7,"")
B21: F8 | C21: =Projektinställningar!C31 | D21: =SUMIFS('Egeninsats & Poäng'!G:G,'Egeninsats & Poäng'!C:C,"Anna Lindström",'Egeninsats & Poäng'!F:F,"F8") | E21: =IFERROR(SUMIFS('Egeninsats & Poäng'!H:H,'Egeninsats & Poäng'!C:C,"Anna Lindström",'Egeninsats & Poäng'!F:F,"F8")/SUMIFS('Egeninsats & Poäng'!G:G,'Egeninsats & Poäng'!C:C,"Anna Lindström",'Egeninsats & Poäng'!F:F,"F8"),"") | F21: =IFERROR(SUMIFS('Egeninsats & Poäng'!I:I,'Egeninsats & Poäng'!C:C,"Anna Lindström",'Egeninsats & Poäng'!F:F,"F8")/SUMIFS('Egeninsats & Poäng'!G:G,'Egeninsats & Poäng'!C:C,"Anna Lindström",'Egeninsats & Poäng'!F:F,"F8"),"") | G21: =SUMIFS('Egeninsats & Poäng'!J:J,'Egeninsats & Poäng'!C:C,"Anna Lindström",'Egeninsats & Poäng'!F:F,"F8") | H21: =IFERROR(SUMIFS('Egeninsats & Poäng'!K:K,'Egeninsats & Poäng'!C:C,"Anna Lindström",'Egeninsats & Poäng'!F:F,"F8")/SUMIFS('Egeninsats & Poäng'!G:G,'Egeninsats & Poäng'!C:C,"Anna Lindström",'Egeninsats & Poäng'!F:F,"F8"),"") | I21: =IFERROR(SUMIFS('Egeninsats & Poäng'!L:L,'Egeninsats & Poäng'!C:C,"Anna Lindström",'Egeninsats & Poäng'!F:F,"F8")/SUMIFS('Egeninsats & Poäng'!G:G,'Egeninsats & Poäng'!C:C,"Anna Lindström",'Egeninsats & Poäng'!F:F,"F8"),"") | J21: =SUMIFS('Egeninsats & Poäng'!M:M,'Egeninsats & Poäng'!C:C,"Anna Lindström",'Egeninsats & Poäng'!F:F,"F8") | K21: =IFERROR(J21/'Equity Dashboard'!E7,"")
B22: TOTALT | D22: =SUM(D14:D21) | G22: =SUM(G14:G21) | J22: =SUM(J14:J21)
B24: DIN ANDEL I RECOUPMENT-VATTENFALLET
B25: Din ägarandel (%) multipliceras med Crew-poolen (50% av netto efter distribution, finansiär och deferred fees).
B26: Scenario A (Litet utfall) | E26: Scenario B (Mellant) | H26: Scenario C (Stort utfall)
B27: Crew-pool: | E27: Crew-pool: | H27: Crew-pool:
B28: ='Waterfall Simulering'!D22 | E28: ='Waterfall Simulering'!E22 | H28: ='Waterfall Simulering'!F22
B29: ='Equity Dashboard'!F7*'Waterfall Simulering'!D22 | E29: ='Equity Dashboard'!F7*'Waterfall Simulering'!E22 | H29: ='Equity Dashboard'!F7*'Waterfall Simulering'!F22
B30: Detta utdrag är konfidentiellt och avsett enbart för mottagaren. Utfärdat av producenten.
B35: =Projektinställningar!C5
B36: Ägarandelsutdrag — Samägande filmproduktion
B39: Per Gustafsson
B40: Producent
B42: TOTALT DEFERRED (SEK) | E42: TOTALA POÄNG | H42: ÄGARANDEL
B43: ='Equity Dashboard'!D8 | E43: ='Equity Dashboard'!E8 | H43: ='Equity Dashboard'!F8
B45: POÄNGHISTORIK PER FAS
B46: Fas | C46: Benämning | D46: Dagar | E46: Cash Fee/dag | F46: Markn.pris/dag | G46: Deferred (SEK) | H46: Grundp./dag | I46: Klassmult. | J46: Poäng | K46: Andel av egna
B47: F1 | C47: =Projektinställningar!C24 | D47: =SUMIFS('Egeninsats & Poäng'!G:G,'Egeninsats & Poäng'!C:C,"Per Gustafsson",'Egeninsats & Poäng'!F:F,"F1") | E47: =IFERROR(SUMIFS('Egeninsats & Poäng'!H:H,'Egeninsats & Poäng'!C:C,"Per Gustafsson",'Egeninsats & Poäng'!F:F,"F1")/SUMIFS('Egeninsats & Poäng'!G:G,'Egeninsats & Poäng'!C:C,"Per Gustafsson",'Egeninsats & Poäng'!F:F,"F1"),"") | F47: =IFERROR(SUMIFS('Egeninsats & Poäng'!I:I,'Egeninsats & Poäng'!C:C,"Per Gustafsson",'Egeninsats & Poäng'!F:F,"F1")/SUMIFS('Egeninsats & Poäng'!G:G,'Egeninsats & Poäng'!C:C,"Per Gustafsson",'Egeninsats & Poäng'!F:F,"F1"),"") | G47: =SUMIFS('Egeninsats & Poäng'!J:J,'Egeninsats & Poäng'!C:C,"Per Gustafsson",'Egeninsats & Poäng'!F:F,"F1") | H47: =IFERROR(SUMIFS('Egeninsats & Poäng'!K:K,'Egeninsats & Poäng'!C:C,"Per Gustafsson",'Egeninsats & Poäng'!F:F,"F1")/SUMIFS('Egeninsats & Poäng'!G:G,'Egeninsats & Poäng'!C:C,"Per Gustafsson",'Egeninsats & Poäng'!F:F,"F1"),"") | I47: =IFERROR(SUMIFS('Egeninsats & Poäng'!L:L,'Egeninsats & Poäng'!C:C,"Per Gustafsson",'Egeninsats & Poäng'!F:F,"F1")/SUMIFS('Egeninsats & Poäng'!G:G,'Egeninsats & Poäng'!C:C,"Per Gustafsson",'Egeninsats & Poäng'!F:F,"F1"),"") | J47: =SUMIFS('Egeninsats & Poäng'!M:M,'Egeninsats & Poäng'!C:C,"Per Gustafsson",'Egeninsats & Poäng'!F:F,"F1") | K47: =IFERROR(J47/'Equity Dashboard'!E8,"")
B48: F2 | C48: =Projektinställningar!C25 | D48: =SUMIFS('Egeninsats & Poäng'!G:G,'Egeninsats & Poäng'!C:C,"Per Gustafsson",'Egeninsats & Poäng'!F:F,"F2") | E48: =IFERROR(SUMIFS('Egeninsats & Poäng'!H:H,'Egeninsats & Poäng'!C:C,"Per Gustafsson",'Egeninsats & Poäng'!F:F,"F2")/SUMIFS('Egeninsats & Poäng'!G:G,'Egeninsats & Poäng'!C:C,"Per Gustafsson",'Egeninsats & Poäng'!F:F,"F2"),"") | F48: =IFERROR(SUMIFS('Egeninsats & Poäng'!I:I,'Egeninsats & Poäng'!C:C,"Per Gustafsson",'Egeninsats & Poäng'!F:F,"F2")/SUMIFS('Egeninsats & Poäng'!G:G,'Egeninsats & Poäng'!C:C,"Per Gustafsson",'Egeninsats & Poäng'!F:F,"F2"),"") | G48: =SUMIFS('Egeninsats & Poäng'!J:J,'Egeninsats & Poäng'!C:C,"Per Gustafsson",'Egeninsats & Poäng'!F:F,"F2") | H48: =IFERROR(SUMIFS('Egeninsats & Poäng'!K:K,'Egeninsats & Poäng'!C:C,"Per Gustafsson",'Egeninsats & Poäng'!F:F,"F2")/SUMIFS('Egeninsats & Poäng'!G:G,'Egeninsats & Poäng'!C:C,"Per Gustafsson",'Egeninsats & Poäng'!F:F,"F2"),"") | I48: =IFERROR(SUMIFS('Egeninsats & Poäng'!L:L,'Egeninsats & Poäng'!C:C,"Per Gustafsson",'Egeninsats & Poäng'!F:F,"F2")/SUMIFS('Egeninsats & Poäng'!G:G,'Egeninsats & Poäng'!C:C,"Per Gustafsson",'Egeninsats & Poäng'!F:F,"F2"),"") | J48: =SUMIFS('Egeninsats & Poäng'!M:M,'Egeninsats & Poäng'!C:C,"Per Gustafsson",'Egeninsats & Poäng'!F:F,"F2") | K48: =IFERROR(J48/'Equity Dashboard'!E8,"")
B49: F3 | C49: =Projektinställningar!C26 | D49: =SUMIFS('Egeninsats & Poäng'!G:G,'Egeninsats & Poäng'!C:C,"Per Gustafsson",'Egeninsats & Poäng'!F:F,"F3") | E49: =IFERROR(SUMIFS('Egeninsats & Poäng'!H:H,'Egeninsats & Poäng'!C:C,"Per Gustafsson",'Egeninsats & Poäng'!F:F,"F3")/SUMIFS('Egeninsats & Poäng'!G:G,'Egeninsats & Poäng'!C:C,"Per Gustafsson",'Egeninsats & Poäng'!F:F,"F3"),"") | F49: =IFERROR(SUMIFS('Egeninsats & Poäng'!I:I,'Egeninsats & Poäng'!C:C,"Per Gustafsson",'Egeninsats & Poäng'!F:F,"F3")/SUMIFS('Egeninsats & Poäng'!G:G,'Egeninsats & Poäng'!C:C,"Per Gustafsson",'Egeninsats & Poäng'!F:F,"F3"),"") | G49: =SUMIFS('Egeninsats & Poäng'!J:J,'Egeninsats & Poäng'!C:C,"Per Gustafsson",'Egeninsats & Poäng'!F:F,"F3") | H49: =IFERROR(SUMIFS('Egeninsats & Poäng'!K:K,'Egeninsats & Poäng'!C:C,"Per Gustafsson",'Egeninsats & Poäng'!F:F,"F3")/SUMIFS('Egeninsats & Poäng'!G:G,'Egeninsats & Poäng'!C:C,"Per Gustafsson",'Egeninsats & Poäng'!F:F,"F3"),"") | I49: =IFERROR(SUMIFS('Egeninsats & Poäng'!L:L,'Egeninsats & Poäng'!C:C,"Per Gustafsson",'Egeninsats & Poäng'!F:F,"F3")/SUMIFS('Egeninsats & Poäng'!G:G,'Egeninsats & Poäng'!C:C,"Per Gustafsson",'Egeninsats & Poäng'!F:F,"F3"),"") | J49: =SUMIFS('Egeninsats & Poäng'!M:M,'Egeninsats & Poäng'!C:C,"Per Gustafsson",'Egeninsats & Poäng'!F:F,"F3") | K49: =IFERROR(J49/'Equity Dashboard'!E8,"")
B50: F4 | C50: =Projektinställningar!C27 | D50: =SUMIFS('Egeninsats & Poäng'!G:G,'Egeninsats & Poäng'!C:C,"Per Gustafsson",'Egeninsats & Poäng'!F:F,"F4") | E50: =IFERROR(SUMIFS('Egeninsats & Poäng'!H:H,'Egeninsats & Poäng'!C:C,"Per Gustafsson",'Egeninsats & Poäng'!F:F,"F4")/SUMIFS('Egeninsats & Poäng'!G:G,'Egeninsats & Poäng'!C:C,"Per Gustafsson",'Egeninsats & Poäng'!F:F,"F4"),"") | F50: =IFERROR(SUMIFS('Egeninsats & Poäng'!I:I,'Egeninsats & Poäng'!C:C,"Per Gustafsson",'Egeninsats & Poäng'!F:F,"F4")/SUMIFS('Egeninsats & Poäng'!G:G,'Egeninsats & Poäng'!C:C,"Per Gustafsson",'Egeninsats & Poäng'!F:F,"F4"),"") | G50: =SUMIFS('Egeninsats & Poäng'!J:J,'Egeninsats & Poäng'!C:C,"Per Gustafsson",'Egeninsats & Poäng'!F:F,"F4") | H50: =IFERROR(SUMIFS('Egeninsats & Poäng'!K:K,'Egeninsats & Poäng'!C:C,"Per Gustafsson",'Egeninsats & Poäng'!F:F,"F4")/SUMIFS('Egeninsats & Poäng'!G:G,'Egeninsats & Poäng'!C:C,"Per Gustafsson",'Egeninsats & Poäng'!F:F,"F4"),"") | I50: =IFERROR(SUMIFS('Egeninsats & Poäng'!L:L,'Egeninsats & Poäng'!C:C,"Per Gustafsson",'Egeninsats & Poäng'!F:F,"F4")/SUMIFS('Egeninsats & Poäng'!G:G,'Egeninsats & Poäng'!C:C,"Per Gustafsson",'Egeninsats & Poäng'!F:F,"F4"),"") | J50: =SUMIFS('Egeninsats & Poäng'!M:M,'Egeninsats & Poäng'!C:C,"Per Gustafsson",'Egeninsats & Poäng'!F:F,"F4") | K50: =IFERROR(J50/'Equity Dashboard'!E8,"")
B51: F5 | C51: =Projektinställningar!C28 | D51: =SUMIFS('Egeninsats & Poäng'!G:G,'Egeninsats & Poäng'!C:C,"Per Gustafsson",'Egeninsats & Poäng'!F:F,"F5") | E51: =IFERROR(SUMIFS('Egeninsats & Poäng'!H:H,'Egeninsats & Poäng'!C:C,"Per Gustafsson",'Egeninsats & Poäng'!F:F,"F5")/SUMIFS('Egeninsats & Poäng'!G:G,'Egeninsats & Poäng'!C:C,"Per Gustafsson",'Egeninsats & Poäng'!F:F,"F5"),"") | F51: =IFERROR(SUMIFS('Egeninsats & Poäng'!I:I,'Egeninsats & Poäng'!C:C,"Per Gustafsson",'Egeninsats & Poäng'!F:F,"F5")/SUMIFS('Egeninsats & Poäng'!G:G,'Egeninsats & Poäng'!C:C,"Per Gustafsson",'Egeninsats & Poäng'!F:F,"F5"),"") | G51: =SUMIFS('Egeninsats & Poäng'!J:J,'Egeninsats & Poäng'!C:C,"Per Gustafsson",'Egeninsats & Poäng'!F:F,"F5") | H51: =IFERROR(SUMIFS('Egeninsats & Poäng'!K:K,'Egeninsats & Poäng'!C:C,"Per Gustafsson",'Egeninsats & Poäng'!F:F,"F5")/SUMIFS('Egeninsats & Poäng'!G:G,'Egeninsats & Poäng'!C:C,"Per Gustafsson",'Egeninsats & Poäng'!F:F,"F5"),"") | I51: =IFERROR(SUMIFS('Egeninsats & Poäng'!L:L,'Egeninsats & Poäng'!C:C,"Per Gustafsson",'Egeninsats & Poäng'!F:F,"F5")/SUMIFS('Egeninsats & Poäng'!G:G,'Egeninsats & Poäng'!C:C,"Per Gustafsson",'Egeninsats & Poäng'!F:F,"F5"),"") | J51: =SUMIFS('Egeninsats & Poäng'!M:M,'Egeninsats & Poäng'!C:C,"Per Gustafsson",'Egeninsats & Poäng'!F:F,"F5") | K51: =IFERROR(J51/'Equity Dashboard'!E8,"")
B52: F6 | C52: =Projektinställningar!C29 | D52: =SUMIFS('Egeninsats & Poäng'!G:G,'Egeninsats & Poäng'!C:C,"Per Gustafsson",'Egeninsats & Poäng'!F:F,"F6") | E52: =IFERROR(SUMIFS('Egeninsats & Poäng'!H:H,'Egeninsats & Poäng'!C:C,"Per Gustafsson",'Egeninsats & Poäng'!F:F,"F6")/SUMIFS('Egeninsats & Poäng'!G:G,'Egeninsats & Poäng'!C:C,"Per Gustafsson",'Egeninsats & Poäng'!F:F,"F6"),"") | F52: =IFERROR(SUMIFS('Egeninsats & Poäng'!I:I,'Egeninsats & Poäng'!C:C,"Per Gustafsson",'Egeninsats & Poäng'!F:F,"F6")/SUMIFS('Egeninsats & Poäng'!G:G,'Egeninsats & Poäng'!C:C,"Per Gustafsson",'Egeninsats & Poäng'!F:F,"F6"),"") | G52: =SUMIFS('Egeninsats & Poäng'!J:J,'Egeninsats & Poäng'!C:C,"Per Gustafsson",'Egeninsats & Poäng'!F:F,"F6") | H52: =IFERROR(SUMIFS('Egeninsats & Poäng'!K:K,'Egeninsats & Poäng'!C:C,"Per Gustafsson",'Egeninsats & Poäng'!F:F,"F6")/SUMIFS('Egeninsats & Poäng'!G:G,'Egeninsats & Poäng'!C:C,"Per Gustafsson",'Egeninsats & Poäng'!F:F,"F6"),"") | I52: =IFERROR(SUMIFS('Egeninsats & Poäng'!L:L,'Egeninsats & Poäng'!C:C,"Per Gustafsson",'Egeninsats & Poäng'!F:F,"F6")/SUMIFS('Egeninsats & Poäng'!G:G,'Egeninsats & Poäng'!C:C,"Per Gustafsson",'Egeninsats & Poäng'!F:F,"F6"),"") | J52: =SUMIFS('Egeninsats & Poäng'!M:M,'Egeninsats & Poäng'!C:C,"Per Gustafsson",'Egeninsats & Poäng'!F:F,"F6") | K52: =IFERROR(J52/'Equity Dashboard'!E8,"")
B53: F7 | C53: =Projektinställningar!C30 | D53: =SUMIFS('Egeninsats & Poäng'!G:G,'Egeninsats & Poäng'!C:C,"Per Gustafsson",'Egeninsats & Poäng'!F:F,"F7") | E53: =IFERROR(SUMIFS('Egeninsats & Poäng'!H:H,'Egeninsats & Poäng'!C:C,"Per Gustafsson",'Egeninsats & Poäng'!F:F,"F7")/SUMIFS('Egeninsats & Poäng'!G:G,'Egeninsats & Poäng'!C:C,"Per Gustafsson",'Egeninsats & Poäng'!F:F,"F7"),"") | F53: =IFERROR(SUMIFS('Egeninsats & Poäng'!I:I,'Egeninsats & Poäng'!C:C,"Per Gustafsson",'Egeninsats & Poäng'!F:F,"F7")/SUMIFS('Egeninsats & Poäng'!G:G,'Egeninsats & Poäng'!C:C,"Per Gustafsson",'Egeninsats & Poäng'!F:F,"F7"),"") | G53: =SUMIFS('Egeninsats & Poäng'!J:J,'Egeninsats & Poäng'!C:C,"Per Gustafsson",'Egeninsats & Poäng'!F:F,"F7") | H53: =IFERROR(SUMIFS('Egeninsats & Poäng'!K:K,'Egeninsats & Poäng'!C:C,"Per Gustafsson",'Egeninsats & Poäng'!F:F,"F7")/SUMIFS('Egeninsats & Poäng'!G:G,'Egeninsats & Poäng'!C:C,"Per Gustafsson",'Egeninsats & Poäng'!F:F,"F7"),"") | I53: =IFERROR(SUMIFS('Egeninsats & Poäng'!L:L,'Egeninsats & Poäng'!C:C,"Per Gustafsson",'Egeninsats & Poäng'!F:F,"F7")/SUMIFS('Egeninsats & Poäng'!G:G,'Egeninsats & Poäng'!C:C,"Per Gustafsson",'Egeninsats & Poäng'!F:F,"F7"),"") | J53: =SUMIFS('Egeninsats & Poäng'!M:M,'Egeninsats & Poäng'!C:C,"Per Gustafsson",'Egeninsats & Poäng'!F:F,"F7") | K53: =IFERROR(J53/'Equity Dashboard'!E8,"")
B54: F8 | C54: =Projektinställningar!C31 | D54: =SUMIFS('Egeninsats & Poäng'!G:G,'Egeninsats & Poäng'!C:C,"Per Gustafsson",'Egeninsats & Poäng'!F:F,"F8") | E54: =IFERROR(SUMIFS('Egeninsats & Poäng'!H:H,'Egeninsats & Poäng'!C:C,"Per Gustafsson",'Egeninsats & Poäng'!F:F,"F8")/SUMIFS('Egeninsats & Poäng'!G:G,'Egeninsats & Poäng'!C:C,"Per Gustafsson",'Egeninsats & Poäng'!F:F,"F8"),"") | F54: =IFERROR(SUMIFS('Egeninsats & Poäng'!I:I,'Egeninsats & Poäng'!C:C,"Per Gustafsson",'Egeninsats & Poäng'!F:F,"F8")/SUMIFS('Egeninsats & Poäng'!G:G,'Egeninsats & Poäng'!C:C,"Per Gustafsson",'Egeninsats & Poäng'!F:F,"F8"),"") | G54: =SUMIFS('Egeninsats & Poäng'!J:J,'Egeninsats & Poäng'!C:C,"Per Gustafsson",'Egeninsats & Poäng'!F:F,"F8") | H54: =IFERROR(SUMIFS('Egeninsats & Poäng'!K:K,'Egeninsats & Poäng'!C:C,"Per Gustafsson",'Egeninsats & Poäng'!F:F,"F8")/SUMIFS('Egeninsats & Poäng'!G:G,'Egeninsats & Poäng'!C:C,"Per Gustafsson",'Egeninsats & Poäng'!F:F,"F8"),"") | I54: =IFERROR(SUMIFS('Egeninsats & Poäng'!L:L,'Egeninsats & Poäng'!C:C,"Per Gustafsson",'Egeninsats & Poäng'!F:F,"F8")/SUMIFS('Egeninsats & Poäng'!G:G,'Egeninsats & Poäng'!C:C,"Per Gustafsson",'Egeninsats & Poäng'!F:F,"F8"),"") | J54: =SUMIFS('Egeninsats & Poäng'!M:M,'Egeninsats & Poäng'!C:C,"Per Gustafsson",'Egeninsats & Poäng'!F:F,"F8") | K54: =IFERROR(J54/'Equity Dashboard'!E8,"")
...
